<?xml version="1.0"?>
<sdf version="1.8">
  <model name="t0_robot">
    <link name="base_link">
      <pose>0 0 0.06 0 0 0</pose>
      <inertial>
        <mass>8.0</mass>
        <inertia>
          <ixx>0.08</ixx><iyy>0.12</iyy><izz>0.14</izz>
        </inertia>
      </inertial>
      <collision name="body">
        <geometry><box><size>0.36 0.28 0.12</size></box></geometry>
      </collision>
      <visual name="body">
        <geometry><box><size>0.36 0.28 0.12</size></box></geometry>
        <material>
          <ambient>0.15 0.55 0.85 1</ambient>
          <diffuse>0.25 0.75 1.0 1</diffuse>
        </material>
      </visual>
      <visual name="nose">
        <pose>0.18 0 0 0 0 0</pose>
        <geometry><box><size>0.04 0.08 0.04</size></box></geometry>
        <material>
          <ambient>0.9 0.9 0.2 1</ambient>
          <diffuse>1 1 0.35 1</diffuse>
        </material>
      </visual>
    </link>

    <link name="left_wheel">
      <pose>0 0.14 0.05 1.5707 0 0</pose>
      <inertial><mass>0.5</mass></inertial>
      <collision name="collision">
        <geometry><cylinder><radius>0.05</radius><length>0.04</length></cylinder></geometry>
      </collision>
      <visual name="visual">
        <geometry><cylinder><radius>0.05</radius><length>0.04</length></cylinder></geometry>
        <material><ambient>0.1 0.1 0.1 1</ambient><diffuse>0.15 0.15 0.15 1</diffuse></material>
      </visual>
    </link>
    <joint name="left_wheel_joint" type="revolute">
      <parent>base_link</parent><child>left_wheel</child>
      <axis><xyz>0 1 0</xyz></axis>
    </joint>

    <link name="right_wheel">
      <pose>0 -0.14 0.05 1.5707 0 0</pose>
      <inertial><mass>0.5</mass></inertial>
      <collision name="collision">
        <geometry><cylinder><radius>0.05</radius><length>0.04</length></cylinder></geometry>
      </collision>
      <visual name="visual">
        <geometry><cylinder><radius>0.05</radius><length>0.04</length></cylinder></geometry>
        <material><ambient>0.1 0.1 0.1 1</ambient><diffuse>0.15 0.15 0.15 1</diffuse></material>
      </visual>
    </link>
    <joint name="right_wheel_joint" type="revolute">
      <parent>base_link</parent><child>right_wheel</child>
      <axis><xyz>0 1 0</xyz></axis>
    </joint>

    <link name="caster">
      <pose>-0.14 0 0.03 0 0 0</pose>
      <inertial><mass>0.2</mass></inertial>
      <collision name="collision">
        <geometry><sphere><radius>0.03</radius></sphere></geometry>
      </collision>
      <visual name="visual">
        <geometry><sphere><radius>0.03</radius></sphere></geometry>
        <material><ambient>0.2 0.2 0.2 1</ambient><diffuse>0.3 0.3 0.3 1</diffuse></material>
      </visual>
    </link>
    <joint name="caster_joint" type="ball">
      <parent>base_link</parent><child>caster</child>
    </joint>

    <plugin
      filename="libgz-sim-diff-drive-system.so"
      name="gz::sim::systems::DiffDrive">
      <left_joint>left_wheel_joint</left_joint>
      <right_joint>right_wheel_joint</right_joint>
      <wheel_separation>0.28</wheel_separation>
      <wheel_radius>0.05</wheel_radius>
      <topic>/cmd_vel</topic>
      <odom_topic>odom</odom_topic>
      <tf_topic>tf</tf_topic>
      <frame_id>odom</frame_id>
      <child_frame_id>base_link</child_frame_id>
      <publish_odom_tf>true</publish_odom_tf>
      <odom_publish_frequency>30</odom_publish_frequency>
    </plugin>
  </model>
</sdf>
