<?xml version="1.0"?>
<robot name="t0_robot">
  <link name="base_footprint"/>
  <link name="base_link">
    <visual>
      <geometry><box size="0.36 0.28 0.12"/></geometry>
      <material name="blue"><color rgba="0.25 0.75 1.0 1"/></material>
    </visual>
    <collision>
      <geometry><box size="0.36 0.28 0.12"/></geometry>
    </collision>
    <inertial>
      <mass value="8.0"/>
      <inertia ixx="0.08" ixy="0" ixz="0" iyy="0.12" iyz="0" izz="0.14"/>
    </inertial>
  </link>
  <joint name="base_footprint_joint" type="fixed">
    <parent link="base_footprint"/><child link="base_link"/>
    <origin xyz="0 0 0.05" rpy="0 0 0"/>
  </joint>
  <link name="left_wheel">
    <visual>
      <origin xyz="0 0 0" rpy="1.5707 0 0"/>
      <geometry><cylinder radius="0.05" length="0.04"/></geometry>
      <material name="black"><color rgba="0.15 0.15 0.15 1"/></material>
    </visual>
    <collision>
      <origin xyz="0 0 0" rpy="1.5707 0 0"/>
      <geometry><cylinder radius="0.05" length="0.04"/></geometry>
    </collision>
  </link>
  <joint name="left_wheel_joint" type="continuous">
    <parent link="base_link"/><child link="left_wheel"/>
    <origin xyz="0 0.14 0.05" rpy="0 0 0"/>
    <axis xyz="0 1 0"/>
  </joint>
  <link name="right_wheel">
    <visual>
      <origin xyz="0 0 0" rpy="1.5707 0 0"/>
      <geometry><cylinder radius="0.05" length="0.04"/></geometry>
      <material name="black"><color rgba="0.15 0.15 0.15 1"/></material>
    </visual>
    <collision>
      <origin xyz="0 0 0" rpy="1.5707 0 0"/>
      <geometry><cylinder radius="0.05" length="0.04"/></geometry>
    </collision>
  </link>
  <joint name="right_wheel_joint" type="continuous">
    <parent link="base_link"/><child link="right_wheel"/>
    <origin xyz="0 -0.14 0.05" rpy="0 0 0"/>
    <axis xyz="0 1 0"/>
  </joint>
</robot>
